<?xml version="1.0"?>
<robot xmlns:xacro="http://www.ros.org/wiki/xacro">

    <joint name="camera_joint" type="revolute">
        <parent link="body_link"/>
        <child link="camera_link"/>
        <origin xyz="0.05 0 1.1" rpy="0 0 0"/>
        <axis xyz="0 1 0"/>
        <limit effort="1000.0" lower="0.0" upper="0.548" velocity="0.5"/>
    </joint>

    <link name="camera_link">
        <visual>
            <geometry>
                <box size="0.04 0.07 0.04"/>
            </geometry>
            <material name="red"/>
        </visual>
        <xacro:inertial_box mass="0.1" x="0.04" y="0.07" z="0.04">
            <origin xyz="0 0 0" rpy="0 0 0"/>
        </xacro:inertial_box>
    </link>

    <joint name="camera_optical_joint" type="fixed">
        <parent link="camera_link"/>
        <child link="camera_link_optical"/>
        <origin xyz="0 0 0" rpy="${-pi/2} 0 ${-pi/2}"/>
    </joint>

    <link name="camera_link_optical"></link>

    <gazebo reference="camera_link">
        <material>Gazebo/Red</material>

        <sensor name="camera" type="camera">
            <pose> 0 0 0 0 0 0 </pose>
            <visualize>true</visualize>
            <update_rate>10</update_rate>
            <camera>
                <horizontal_fov>1.089</horizontal_fov>
                <image>
                    <format>R8G8B8</format>
                    <width>640</width>
                    <height>480</height>
                </image>
                <clip>
                    <near>0.05</near>
                    <far>8.0</far>
                </clip>
            </camera>
            <plugin name="camera_controller" filename="libgazebo_ros_camera.so">
                <frame_name>camera_link_optical</frame_name>
            </plugin>
        </sensor>
    </gazebo>

</robot>